Workbook

Sheet Merchants
A1: merchant_id | B1: merchant_name | C1: category | D1: region
A2: 1 | B2: Merchant_001 | C2: ecommerce | D2: South
A3: 2 | B3: Merchant_002 | C3: grocery | D3: West
A4: 3 | B4: Merchant_003 | C4: grocery | D4: East
A5: 4 | B5: Merchant_004 | C5: ecommerce | D5: East
A6: 5 | B6: Merchant_005 | C6: recharge | D6: South
A7: 6 | B7: Merchant_006 | C7: food_delivery | D7: South
A8: 7 | B8: Merchant_007 | C8: food_delivery | D8: East
A9: 8 | B9: Merchant_008 | C9: food_delivery | D9: North
A10: 9 | B10: Merchant_009 | C10: ecommerce | D10: North
A11: 10 | B11: Merchant_010 | C11: grocery | D11: West
A12: 11 | B12: Merchant_011 | C12: ecommerce | D12: North
A13: 12 | B13: Merchant_012 | C13: ecommerce | D13: East
... A41: 40 | B41: Merchant_040 | C41: entertainment | D41: South

Sheet Transactions
A1: transaction_id | B1: user_id | C1: merchant_id | D1: transaction_time | E1: amount_inr | F1: payment_method | G1: status | H1: risk_score | I1: merchant_name | J1: category | K1: region | L1: MDR Fee % | M1: transaction_date | N1: daily_merchant_total | O1: merchant_day_classification
A2: TXN100000 | B2: 350 | C2: 16 | D2: 46051.467 | E2: 2999 | F2: Wallet | G2: captured | H2: 85 | I2: =IFERROR(VLOOKUP(C2,Merchants!$A$2:$D$41,2,FALSE),"Merchant not found") -> Merchant_016 | J2: =IFERROR(VLOOKUP(C2,Merchants!$A$2:$D$41,3,FALSE),"Merchant not found") -> bill_payment | K2: =IFERROR(VLOOKUP(C2,Merchants!$A$2:$D$41,4,FALSE),"Merchant not found") -> West | L2: =HLOOKUP(F2,Fee_lookup!$A$2:$E$3,2,FALSE) -> 0.0005 | M2: =INT(D2) -> 46051 | N2: =SUMIFS($E:$E,$C:$C,C2,$M:$M,M2) -> 2999 | O2: =IF(AND(N2>5000,K2<>"East"),"High-Value Merchant Day","Normal Merchant Day") -> Normal Merchant Day
A3: TXN100001 | B3: 287 | C3: 27 | D3: 46026.492 | E3: 49 | F3: UPI | G3: captured | H3: 79 | I3: =IFERROR(VLOOKUP(C3,Merchants!$A$2:$D$41,2,FALSE),"Merchant not found") -> Merchant_027 | J3: =IFERROR(VLOOKUP(C3,Merchants!$A$2:$D$41,3,FALSE),"Merchant not found") -> ecommerce | K3: =IFERROR(VLOOKUP(C3,Merchants!$A$2:$D$41,4,FALSE),"Merchant not found") -> North | L3: =HLOOKUP(F3,Fee_lookup!$A$2:$E$3,2,FALSE) -> 0.0002 | M3: =INT(D3) -> 46026 | N3: =SUMIFS($E:$E,$C:$C,C3,$M:$M,M3) -> 49 | O3: =IF(AND(N3>5000,K3<>"East"),"High-Value Merchant Day","Normal Merchant Day") -> Normal Merchant Day
A4: TXN100002 | B4: 122 | C4: 11 | D4: 46046.208 | E4: 1499 | F4: Wallet | G4: captured | H4: 22 | I4: =IFERROR(VLOOKUP(C4,Merchants!$A$2:$D$41,2,FALSE),"Merchant not found") -> Merchant_011 | J4: =IFERROR(VLOOKUP(C4,Merchants!$A$2:$D$41,3,FALSE),"Merchant not found") -> ecommerce | K4: =IFERROR(VLOOKUP(C4,Merchants!$A$2:$D$41,4,FALSE),"Merchant not found") -> North | L4: =HLOOKUP(F4,Fee_lookup!$A$2:$E$3,2,FALSE) -> 0.0005 | M4: =INT(D4) -> 46046 | N4: =SUMIFS($E:$E,$C:$C,C4,$M:$M,M4) -> 1798 | O4: =IF(AND(N4>5000,K4<>"East"),"High-Value Merchant Day","Normal Merchant Day") -> Normal Merchant Day
A5: TXN100003 | B5: 92 | C5: 22 | D5: 46051.542 | E5: 49 | F5: Netbanking | G5: captured | H5: 100 | I5: =IFERROR(VLOOKUP(C5,Merchants!$A$2:$D$41,2,FALSE),"Merchant not found") -> Merchant_022 | J5: =IFERROR(VLOOKUP(C5,Merchants!$A$2:$D$41,3,FALSE),"Merchant not found") -> travel | K5: =IFERROR(VLOOKUP(C5,Merchants!$A$2:$D$41,4,FALSE),"Merchant not found") -> South | L5: =HLOOKUP(F5,Fee_lookup!$A$2:$E$3,2,FALSE) -> 0.01 | M5: =INT(D5) -> 46051 | N5: =SUMIFS($E:$E,$C:$C,C5,$M:$M,M5) -> 49 | O5: =IF(AND(N5>5000,K5<>"East"),"High-Value Merchant Day","Normal Merchant Day") -> Normal Merchant Day
A6: TXN100004 | B6: 343 | C6: 16 | D6: 46052.577 | E6: 99 | F6: UPI | G6: captured | H6: 34 | I6: =IFERROR(VLOOKUP(C6,Merchants!$A$2:$D$41,2,FALSE),"Merchant not found") -> Merchant_016 | J6: =IFERROR(VLOOKUP(C6,Merchants!$A$2:$D$41,3,FALSE),"Merchant not found") -> bill_payment | K6: =IFERROR(VLOOKUP(C6,Merchants!$A$2:$D$41,4,FALSE),"Merchant not found") -> West | L6: =HLOOKUP(F6,Fee_lookup!$A$2:$E$3,2,FALSE) -> 0.0002 | M6: =INT(D6) -> 46052 | N6: =SUMIFS($E:$E,$C:$C,C6,$M:$M,M6) -> 898 | O6: =IF(AND(N6>5000,K6<>"East"),"High-Value Merchant Day","Normal Merchant Day") -> Normal Merchant Day
A7: TXN100005 | B7: 196 | C7: 3 | D7: 46028.921 | E7: 99 | F7: UPI | G7: captured | H7: 60 | I7: =IFERROR(VLOOKUP(C7,Merchants!$A$2:$D$41,2,FALSE),"Merchant not found") -> Merchant_003 | J7: =IFERROR(VLOOKUP(C7,Merchants!$A$2:$D$41,3,FALSE),"Merchant not found") -> grocery | K7: =IFERROR(VLOOKUP(C7,Merchants!$A$2:$D$41,4,FALSE),"Merchant not found") -> East | L7: =HLOOKUP(F7,Fee_lookup!$A$2:$E$3,2,FALSE) -> 0.0002 | M7: =INT(D7) -> 46028 | N7: =SUMIFS($E:$E,$C:$C,C7,$M:$M,M7) -> 898 | O7: =IF(AND(N7>5000,K7<>"East"),"High-Value Merchant Day","Normal Merchant Day") -> Normal Merchant Day
A8: TXN100006 | B8: 236 | C8: 23 | D8: 46030.286 | E8: 99 | F8: Wallet | G8: captured | H8: 39 | I8: =IFERROR(VLOOKUP(C8,Merchants!$A$2:$D$41,2,FALSE),"Merchant not found") -> Merchant_023 | J8: =IFERROR(VLOOKUP(C8,Merchants!$A$2:$D$41,3,FALSE),"Merchant not found") -> travel | K8: =IFERROR(VLOOKUP(C8,Merchants!$A$2:$D$41,4,FALSE),"Merchant not found") -> North | L8: =HLOOKUP(F8,Fee_lookup!$A$2:$E$3,2,FALSE) -> 0.0005 | M8: =INT(D8) -> 46030 | N8: =SUMIFS($E:$E,$C:$C,C8,$M:$M,M8) -> 99 | O8: =IF(AND(N8>5000,K8<>"East"),"High-Value Merchant Day","Normal Merchant Day") -> Normal Merchant Day
A9: TXN100007 | B9: 13 | C9: 13 | D9: 46049.301 | E9: 99 | F9: UPI | G9: captured | H9: 51 | I9: =IFERROR(VLOOKUP(C9,Merchants!$A$2:$D$41,2,FALSE),"Merchant not found") -> Merchant_013 | J9: =IFERROR(VLOOKUP(C9,Merchants!$A$2:$D$41,3,FALSE),"Merchant not found") -> travel | K9: =IFERROR(VLOOKUP(C9,Merchants!$A$2:$D$41,4,FALSE),"Merchant not found") -> East | L9: =HLOOKUP(F9,Fee_lookup!$A$2:$E$3,2,FALSE) -> 0.0002 | M9: =INT(D9) -> 46049 | N9: =SUMIFS($E:$E,$C:$C,C9,$M:$M,M9) -> 99 | O9: =IF(AND(N9>5000,K9<>"East"),"High-Value Merchant Day","Normal Merchant Day") -> Normal Merchant Day
A10: TXN100008 | B10: 36 | C10: 18 | D10: 46033.372 | E10: 799 | F10: UPI | G10: captured | H10: 44 | I10: =IFERROR(VLOOKUP(C10,Merchants!$A$2:$D$41,2,FALSE),"Merchant not found") -> Merchant_018 | J10: =IFERROR(VLOOKUP(C10,Merchants!$A$2:$D$41,3,FALSE),"Merchant not found") -> grocery | K10: =IFERROR(VLOOKUP(C10,Merchants!$A$2:$D$41,4,FALSE),"Merchant not found") -> West | L10: =HLOOKUP(F10,Fee_lookup!$A$2:$E$3,2,FALSE) -> 0.0002 | M10: =INT(D10) -> 46033 | N10: =SUMIFS($E:$E,$C:$C,C10,$M:$M,M10) -> 799 | O10: =IF(AND(N10>5000,K10<>"East"),"High-Value Merchant Day","Normal Merchant Day") -> Normal Merchant Day
A11: TXN100009 | B11: 348 | C11: 35 | D11: 46043.684 | E11: 299 | F11: UPI | G11: captured | H11: 42 | I11: =IFERROR(VLOOKUP(C11,Merchants!$A$2:$D$41,2,FALSE),"Merchant not found") -> Merchant_035 | J11: =IFERROR(VLOOKUP(C11,Merchants!$A$2:$D$41,3,FALSE),"Merchant not found") -> recharge | K11: =IFERROR(VLOOKUP(C11,Merchants!$A$2:$D$41,4,FALSE),"Merchant not found") -> East | L11: =HLOOKUP(F11,Fee_lookup!$A$2:$E$3,2,FALSE) -> 0.0002 | M11: =INT(D11) -> 46043 | N11: =SUMIFS($E:$E,$C:$C,C11,$M:$M,M11) -> 299 | O11: =IF(AND(N11>5000,K11<>"East"),"High-Value Merchant Day","Normal Merchant Day") -> Normal Merchant Day
A12: TXN100010 | B12: 134 | C12: 12 | D12: 46023.164 | E12: 49 | F12: UPI | G12: captured | H12: 74 | I12: =IFERROR(VLOOKUP(C12,Merchants!$A$2:$D$41,2,FALSE),"Merchant not found") -> Merchant_012 | J12: =IFERROR(VLOOKUP(C12,Merchants!$A$2:$D$41,3,FALSE),"Merchant not found") -> ecommerce | K12: =IFERROR(VLOOKUP(C12,Merchants!$A$2:$D$41,4,FALSE),"Merchant not found") -> East | L12: =HLOOKUP(F12,Fee_lookup!$A$2:$E$3,2,FALSE) -> 0.0002 | M12: =INT(D12) -> 46023 | N12: =SUMIFS($E:$E,$C:$C,C12,$M:$M,M12) -> 548 | O12: =IF(AND(N12>5000,K12<>"East"),"High-Value Merchant Day","Normal Merchant Day") -> Normal Merchant Day
A13: TXN100011 | B13: 306 | C13: 28 | D13: 46031.046 | E13: 2999 | F13: Card | G13: failed | H13: 44 | I13: =IFERROR(VLOOKUP(C13,Merchants!$A$2:$D$41,2,FALSE),"Merchant not found") -> Merchant_028 | J13: =IFERROR(VLOOKUP(C13,Merchants!$A$2:$D$41,3,FALSE),"Merchant not found") -> ecommerce | K13: =IFERROR(VLOOKUP(C13,Merchants!$A$2:$D$41,4,FALSE),"Merchant not found") -> South | L13: =HLOOKUP(F13,Fee_lookup!$A$2:$E$3,2,FALSE) -> 0.015 | M13: =INT(D13) -> 46031 | N13: =SUMIFS($E:$E,$C:$C,C13,$M:$M,M13) -> 2999 | O13: =IF(AND(N13>5000,K13<>"East"),"High-Value Merchant Day","Normal Merchant Day") -> Normal Merchant Day
... A548: TXN300031 | B548: 345 | C548: 12 | D548: 46045.377 | E548: 399 | F548: Card | G548: captured | H548: 69 | I548: =IFERROR(VLOOKUP(C548,Merchants!$A$2:$D$41,2,FALSE),"Merchant not found") -> Merchant_012 | J548: =IFERROR(VLOOKUP(C548,Merchants!$A$2:$D$41,3,FALSE),"Merchant not found") -> ecommerce | K548: =IFERROR(VLOOKUP(C548,Merchants!$A$2:$D$41,4,FALSE),"Merchant not found") -> East | L548: =HLOOKUP(F548,Fee_lookup!$A$2:$E$3,2,FALSE) -> 0.015 | M548: =INT(D548) -> 46045 | N548: =SUMIFS($E:$E,$C:$C,C548,$M:$M,M548) -> 448 | O548: =IF(AND(N548>5000,K548<>"East"),"High-Value Merchant Day","Normal Merchant Day") -> Normal Merchant Day

Sheet Fee_lookup
A1: A | B1: B | C1: C | D1: D | E1: E
A2: Payment Method | B2: UPI | C2: Wallet | D2: Card | E2: Netbanking
A3: MDR Fee % | B3: 0.0002 | C3: 0.0005 | D3: 0.015 | E3: 0.01

Sheet Daily_Merchan_Pivot
A3: Row Labels | B3: Sum of amount_inr | C3: Count of transaction_id
A4: 1 | B4: 10441 | C4: 9
A5: 46027 | B5: 1499 | C5: 1
A6: 46028 | B6: 149 | C6: 1
A7: 46031 | B7: 5048 | C7: 2
A8: 46033 | B8: 299 | C8: 1
A9: 46034 | B9: 149 | C9: 1
A10: 46039 | B10: 149 | C10: 1
A11: 46045 | B11: 3148 | C11: 2
A12: 2 | B12: 3640 | C12: 10
A13: 46029 | B13: 499 | C13: 1
A14: 46030 | B14: 299 | C14: 1
A15: 46034 | B15: 348 | C15: 2
... A486: 46052 | B486: 499 | C486: 1
A487: Grand Total | B487: 382603 | C487: 547

Sheet Merchant_Status_Summary
B3: Column Labels
B4: captured | D4: chargeback | F4: failed | H4: Total Sum of amount_inr | I4: Total Count of transaction_id
A5: Row Labels | B5: Sum of amount_inr | C5: Count of transaction_id | D5: Sum of amount_inr | E5: Count of transaction_id | F5: Sum of amount_inr | G5: Count of transaction_id
A6: 1 | B6: 10142 | C6: 8 | F6: 299 | G6: 1 | H6: 10441 | I6: 9
A7: 2 | B7: 3640 | C7: 10 | H7: 3640 | I7: 10
A8: 3 | B8: 8084 | C8: 16 | D8: 149 | E8: 1 | H8: 8233 | I8: 17
A9: 4 | B9: 6941 | C9: 9 | H9: 6941 | I9: 9
A10: 5 | B10: 5340 | C10: 10 | F10: 499 | G10: 1 | H10: 5839 | I10: 11
A11: 6 | B11: 6637 | C11: 13 | D11: 799 | E11: 1 | H11: 7436 | I11: 14
A12: 7 | B12: 11638 | C12: 12 | D12: 1999 | E12: 1 | F12: 2297 | G12: 3 | H12: 15934 | I12: 16
A13: 8 | B13: 7086 | C13: 14 | D13: 49 | E13: 1 | F13: 299 | G13: 1 | H13: 7434 | I13: 16
A14: 9 | B14: 4485 | C14: 15 | F14: 497 | G14: 3 | H14: 4982 | I14: 18
A15: 10 | B15: 7639 | C15: 11 | D15: 5048 | E15: 2 | F15: 399 | G15: 1 | H15: 13086 | I15: 14
A16: 11 | B16: 9292 | C16: 8 | D16: 149 | E16: 1 | F16: 1499 | G16: 1 | H16: 10940 | I16: 10
A17: 12 | B17: 9389 | C17: 11 | F17: 998 | G17: 2 | H17: 10387 | I17: 13
A18: 13 | B18: 10390 | C18: 10 | D18: 4999 | E18: 1 | F18: 2999 | G18: 1 | H18: 18388 | I18: 12
A19: 14 | B19: 6189 | C19: 11 | F19: 299 | G19: 1 | H19: 6488 | I19: 12
A20: 15 | B20: 7439 | C20: 11 | F20: 399 | G20: 1 | H20: 7838 | I20: 12
A21: 16 | B21: 10183 | C21: 17 | F21: 947 | G21: 3 | H21: 11130 | I21: 20
A22: 17 | B22: 12738 | C22: 12 | F22: 299 | G22: 1 | H22: 13037 | I22: 13
A23: 18 | B23: 7089 | C23: 11 | H23: 7089 | I23: 11
A24: 19 | B24: 7239 | C24: 11 | D24: 4999 | E24: 1 | F24: 598 | G24: 2 | H24: 12836 | I24: 14
A25: 20 | B25: 4192 | C25: 8 | F25: 49 | G25: 1 | H25: 4241 | I25: 9
A26: 21 | B26: 3887 | C26: 13 | F26: 4999 | G26: 1 | H26: 8886 | I26: 14
A27: 22 | B27: 11336 | C27: 14 | F27: 1198 | G27: 2 | H27: 12534 | I27: 16
A28: 23 | B28: 1041 | C28: 9 | D28: 1999 | E28: 1 | H28: 3040 | I28: 10
A29: 24 | B29: 3438 | C29: 12 | D29: 149 | E29: 1 | H29: 3587 | I29: 13
A30: 25 | B30: 12534 | C30: 16 | D30: 2999 | E30: 1 | H30: 15533 | I30: 17
A31: 26 | B31: 2991 | C31: 9 | F31: 2197 | G31: 3 | H31: 5188 | I31: 12
A32: 27 | B32: 8038 | C32: 12 | D32: 4047 | E32: 3 | F32: 1499 | G32: 1 | H32: 13584 | I32: 16
A33: 28 | B33: 4493 | C33: 7 | D33: 1999 | E33: 1 | F33: 3048 | G33: 2 | H33: 9540 | I33: 10
A34: 29 | B34: 5686 | C34: 14 | D34: 3897 | E34: 3 | F34: 3498 | G34: 2 | H34: 13081 | I34: 19
A35: 30 | B35: 7384 | C35: 16 | F35: 499 | G35: 1 | H35: 7883 | I35: 17
A36: 31 | B36: 2640 | C36: 10 | D36: 49 | E36: 1 | F36: 2146 | G36: 4 | H36: 4835 | I36: 15
A37: 32 | B37: 2589 | C37: 11 | D37: 1999 | E37: 1 | F37: 3498 | G37: 2 | H37: 8086 | I37: 14
A38: 33 | B38: 10190 | C38: 10 | F38: 149 | G38: 1 | H38: 10339 | I38: 11
A39: 34 | B39: 9635 | C39: 15 | F39: 399 | G39: 1 | H39: 10034 | I39: 16
A40: 35 | B40: 8688 | C40: 12 | F40: 598 | G40: 2 | H40: 9286 | I40: 14
A41: 36 | B41: 11535 | C41: 15 | D41: 999 | E41: 1 | H41: 12534 | I41: 16
A42: 37 | B42: 10833 | C42: 17 | D42: 1999 | E42: 1 | F42: 99 | G42: 1 | H42: 12931 | I42: 19
...

Sheet Merchant_Day_Comparison
A1: Merchant ID | B1: Total Transactions | C1: Unique Days
A2: 1 | B2: =COUNTIF(Transactions!$C:$C,A2) -> 9 | C2: {=ROWS(_xlfn.UNIQUE(_xlfn._xlws.FILTER(Transactions!$M$2:$M$548,Transactions!$C$2:$C$548=A2)))} -> 7
A3: 2 | B3: =COUNTIF(Transactions!$C:$C,A3) -> 10 | C3: {=ROWS(_xlfn.UNIQUE(_xlfn._xlws.FILTER(Transactions!$M$2:$M$548,Transactions!$C$2:$C$548=A3)))} -> 9
A4: 3 | B4: =COUNTIF(Transactions!$C:$C,A4) -> 17 | C4: {=ROWS(_xlfn.UNIQUE(_xlfn._xlws.FILTER(Transactions!$M$2:$M$548,Transactions!$C$2:$C$548=A4)))} -> 13
A5: 4 | B5: =COUNTIF(Transactions!$C:$C,A5) -> 9 | C5: {=ROWS(_xlfn.UNIQUE(_xlfn._xlws.FILTER(Transactions!$M$2:$M$548,Transactions!$C$2:$C$548=A5)))} -> 7
A6: 5 | B6: =COUNTIF(Transactions!$C:$C,A6) -> 11 | C6: {=ROWS(_xlfn.UNIQUE(_xlfn._xlws.FILTER(Transactions!$M$2:$M$548,Transactions!$C$2:$C$548=A6)))} -> 9

Sheet Documentation
A1: HLOOK UP Assumptions: | C1: Classification rule:
A2: MDR fee assumptions used for demonstration: | C2: High-Value Merchant Day:
A3: UPI: 0.02% | C3: A transaction is classified as High-Value Merchant Day when:
A4: Wallet: 0.05% | C4: 1. The merchant's total transaction amount for that day exceeds INR 5,000.
A5: Card: 1.50% | C5: 2. The merchant's region is not East.
A6: Netbanking: 1.00% | C6: Otherwise, it is classified as Normal Merchant Day.
A7: These are illustrative assumptions used only to demonstrate HLOOKUP.
